Workbook

Sheet Criteria
B3: USE FOR SELECTING ITEMS
B5: Classification Society | E5: Bureau Veritas
B6: Publication | E6: NR467 Steelships - July 2018 edition (entry into force 1 July 2018)
B8: Notations | E8: SHELTERED AREA
B15: SOLAS | E15: =IF(E8="SHELTERED AREA","No (Chapter I, Regulation 1 - Application (a) Unless expressly provided otherwise, the present regulations apply only to ships engaged on international voyages).","Yes.") -> No (Chapter I, Regulation 1 - Application (a) Unless expressly provided otherwise, the present regulations apply only to ships engaged on international voyages).
B17: Steam | E17: No
B19: Gross tonnage | E19: 48
B21: Propulsion engine power | E21: 0
B23: Heated fuel oil tanks | E23: No
B25: Battery room | E25: Yes

Sheet Titles
B2: 622 | C2: =IFERROR(VLOOKUP(B2,Systems!A:B,2,FALSE),"Various") -> Working / control air system | G2: =B2 -> 622
C4: Document information: | F4: Project information:
C5: Revision id | D5: 0 | F5: Client name | G5: Ministry of Transportation of Ontario, Canada
C6: Revision date | D6: 43157 | F6: Client number | G6: 2016-4006
C7: Revision author | D7: FvdM
F8: Classification | G8: Bureau Veritas
C9: Type of vessel | D9: Ro-Pax Ferry | F9: Class notation | G9: I ✠ Hull ✠ Mach, Ro-Ro Passenger Ship, Coastal Area, Ice Class 1B / COLD (-25), ✠ AVM-DPS / ✠ AUT-IMS / Battery System
C10: Project number | D10: DRFe6819 | F10: Flag state | G10: Canada
C11: Yard number | D11: 539317

Sheet Database
A1: Sys Id | B1: Sys name | C1: Subject | D1: Lloyd's Rules and Regulations for the Classification of Special Service Craft | E1: MCA - MSN 1792(M)2 - The Large Commercial Yacht Code (LY2) | F1: Vessel type / Code | G1: IMO IGC / IGC Code / Resolution MSC.391(95) (Liquefied Gases in Bulk) | H1: Bureau Veritas - NR467 - Steel ships | I1: RINA Rules | J1: Bureau Veritas - NR566 - Ships < 500GT | K1: MARPOL | L1: SOLAS | M1: Ministry of Transportation of Ontario - Technical Specification 2016-4006 | N1: Canadian supplement to the SOLAS convention - TP 15211E | O1: Government of Canada - Marine Machinery Regulations (SOR/90-264) | P1: Bureau Veritas - Inland Navigation Vessels | Q1: Danish Maritima Authority (DMA) | R1: Steam | S1: Rel | T1: Obv | U1: ExG | V1: StDE
S2: x | U2: =IF(OR(NOT(H2=""),NOT(M2="")),"","x")
A3: 371 | B3: =IFERROR(VLOOKUP(A3,Systems!A:B,2,FALSE),"Various") -> Ventilation system | C3: Pipes penetrating A or B class divisions | F3: Steelships | H3: 2.3.1 Uninsulated metallic pipes penetrating A or B class divisions shall be of materials having a melting temperature which exceeds 950°C for A-0 and 850°C for B-0 class divisions. | U3: =IF(OR(NOT(H3=""),NOT(M3="")),"","x")
A4: 371 | B4: =IFERROR(VLOOKUP(A4,Systems!A:B,2,FALSE),"Various") -> Ventilation system | C4: Pipes penetrating A or B class divisions | F4: Steelships | H4: 2.3.2 Where the Society may permit the conveying of oil and combustible liquids through accommodation and service spaces, the pipes conveying oil or combustible liquids shall be of a material approved by the Society having regard to the fire risk. | S4: x | T4: x | U4: =IF(OR(NOT(H4=""),NOT(M4="")),"","x")
A5: 371 | B5: =IFERROR(VLOOKUP(A5,Systems!A:B,2,FALSE),"Various") -> Ventilation system | C5: Battery room - warning notice for closing device | F5: Steelships | H5: 6-2-12.5.2 Where a battery compartment ventilator is required to be fitted with a closing device in accordance with Pt 3, Ch 12, 2.3 Closing appliances 2.3.9, a warning notice clearly stating the purpose of the closing device, for example: 'This closing device is to be kept open and only closed in the event of a fire or flooding – Explosive gas atmosphere' is to be provided at the closing device to mitigate the possibility of inadvertent closing of the ventilator. Furthermore, means to lock the battery compartment ventilators in the open position are to be provided. | U5: =IF(OR(NOT(H5=""),NOT(M5="")),"","x")
A6: 371 | B6: =IFERROR(VLOOKUP(A6,Systems!A:B,2,FALSE),"Various") -> Ventilation system | C6: Battery room - free air flow | F6: Battery room | H6: 6-2-12.5.3 Ducted natural ventilation may be employed for battery installations connected to a charging device with a power output of 2 kW or less, provided the exhaust duct can be run directly from the top of the compartment or box to the open air above, with no part of the duct more than 45° from the vertical. A suitable opening is also to be provided below the level of the top of the batteries, so as to ensure a free ventilation air flow. The ventilation duct is to have an area not less than 50 cm2 for every 1 m3 of battery compartment or box volume. | S6: x | U6: =IF(OR(NOT(H6=""),NOT(M6="")),"","x")
A7: 371 | B7: =IFERROR(VLOOKUP(A7,Systems!A:B,2,FALSE),"Various") -> Ventilation system | C7: Battery room - natural or mechanical | F7: Battery room | H7: 6-2-12.5.4 Where natural ventilation is impracticable or insufficient, mechanical ventilation is to be provided, with the air inlet located near the floor and the exhaust at the top of the compartment. | S7: x | U7: =IF(OR(NOT(H7=""),NOT(M7="")),"","x")
A8: 371 | B8: =IFERROR(VLOOKUP(A8,Systems!A:B,2,FALSE),"Various") -> Ventilation system | C8: Battery room - mechanical ventilation for charged batteries | F8: Battery room | H8: 6-2-12.5.5 Mechanical exhaust ventilation complying with Pt 6, Ch 2, 12.5 Ventilation 12.5.9 is to be provided for battery installations connected to a charging device with a total maximum power output of more than 2 kW. Also, to minimise the possibility of oxygen enrichment, compartments and spaces containing batteries with boost charging facilities are to be provided with mechanical exhaust ventilation irrespective of the charging device power output. | S8: x | U8: =IF(OR(NOT(H8=""),NOT(M8="")),"","x")
A9: 371 | B9: =IFERROR(VLOOKUP(A9,Systems!A:B,2,FALSE),"Various") -> Ventilation system | C9: Battery room - separate vent | F9: Battery room | H9: 6-2-12.5.6 The ventilation system for battery compartments and boxes, other than boxes located on open deck or in spaces to which Pt 6, Ch 2, 12.3 Location 12.3.2, Pt 6, Ch 2, 12.3 Location 12.3.3 and Pt 6, Ch 2, 12.3 Location 12.3.5 refer, is to be separate from other ventilation systems. The exhaust ducting is to be led to a location in the open air, where any gases can be safely diluted, away from possible sources of ignition and openings into spaces where gases may accumulate. | S9: x | U9: =IF(OR(NOT(H9=""),NOT(M9="")),"","x")
A10: 371 | B10: =IFERROR(VLOOKUP(A10,Systems!A:B,2,FALSE),"Various") -> Ventilation system | C10: Battery room - fan motor | F10: Battery room | H10: 6-2-12.5.7 Fan motors associated with exhaust ducts from battery compartments are to be placed external to the ducts and the compartments. | S10: x | U10: =IF(OR(NOT(H10=""),NOT(M10="")),"","x")
A11: 371 | B11: =IFERROR(VLOOKUP(A11,Systems!A:B,2,FALSE),"Various") -> Ventilation system | C11: Battery room - fan material | F11: Battery room | H11: 6-2-12.5.8 Ventilating fans for battery compartments are to be so constructed and be of material such as to minimise risk of sparking in the event of the impeller touching the casing. Non-metallic-impellers are to be of an anti-static material. | S11: x | U11: =IF(OR(NOT(H11=""),NOT(M11="")),"","x")
A12: 371 | B12: =IFERROR(VLOOKUP(A12,Systems!A:B,2,FALSE),"Various") -> Ventilation system | C12: Battery room - vent openings | F12: Battery room | H12: 6-2-12.5.9 Battery boxes are to be provided with sufficient ventilation openings located so as to avoid accumulation of flammable gas whilst preventing the entrance of rain or spray. | S12: x | U12: =IF(OR(NOT(H12=""),NOT(M12="")),"","x")
A13: 000 | B13: =IFERROR(VLOOKUP(A13,Systems!A:B,2,FALSE),"Various") -> Project data | C13: General definition | F13: Battery room | H13: A-1-1-1.2.1 Essential service is intended to mean a service necessary for a ship to proceed at sea, be steered or manoeuvred, or undertake activities connected with its operation, and for the safety of life, as far as class is concerned. | S13: x | U13: =IF(OR(NOT(H13=""),NOT(M13="")),"","x")
A14: 100 | B14: =IFERROR(VLOOKUP(A14,Systems!A:B,2,FALSE),"Various") -> Tank arrangement | C14: Adjacent or not | F14: Battery room | H14: B-2-1-2.1.4 Where a corner to corner situation occurs, tanks are not be considered to be adjacent. Adjacent tanks not separated by cofferdams are to have adequate dimensions to ensure easy inspection. | P14: B-2-1-2.1.4 Where a corner to corner situation occurs, tanks are not be considered to be adjacent. Adjacent tanks not separated by cofferdams are to have adequate dimensions to ensure easy inspection. | S14: x | U14: =IF(OR(NOT(H14=""),NOT(M14="")),"","x")
A15: 100 | B15: =IFERROR(VLOOKUP(A15,Systems!A:B,2,FALSE),"Various") -> Tank arrangement | C15: Cofferdams between tanks | F15: Battery room | H15: B-2-2-2.1.1 Cofferdams are to be provided between: - fuel oil tanks and lubricating oil tanks - compartments intended for liquid hydrocarbons (fuel oil, lubricating oil) and compartments intended for fresh water (drinking water, water for propelling machinery and boilers) - compartments intended for liquid hydrocarbons (fuel oil, lubricating oil) and tanks intended for the carriage of liquid foam for fire extinguishing. | P15: B-2-1-2.1.1 Cofferdams are to be provided between compartments intended for liquid hydrocarbons (fuel oil, lubricating oil) and those intended for fresh water (drinking water, water for propelling machinery and boilers) as well as tanks intended for the carriage of liquid foam for fire extinguishing. | S15: x | U15: =IF(OR(NOT(H15=""),NOT(M15="")),"","x")
A16: 100 | B16: =IFERROR(VLOOKUP(A16,Systems!A:B,2,FALSE),"Various") -> Tank arrangement | C16: Exemptions for cofferdams | F16: Battery room | H16: B-2-2-2.1.2 Cofferdams separating: - fuel oil tanks from lubricating oil tanks - lubricating oil tanks from compartments intended for fresh water or boiler feed water - lubricating oil tanks from those intended for the carriage of liquid foam for fire extinguishing may not be required when deemed impracticable or unreasonable by the Society in relation to the characteristics and dimensions of the spaces containing such tanks, provided that: - the thickness of common boundary plates of adjacent tanks is increased, with respect to the thickness obtained according to Ch 7, Sec 1, by 2 mm in the case of tanks carrying fresh water or boiler feed water, and by 1 mm in all other cases - the sum of the throats of the weld fillets at the edges of these plates is not less than the thickness of the plates themselves - the structural test is carried out with a head increased by 1 m with respect to Ch 11, Sec 3, [1.4]. 2.1.3 Vented cofferdam may be required to separate heated oil fuel tanks from enclosed spaces located directly above (see Pt C, Ch 1, Sec 10, [11.7.2], item a)). | P16: B-2-1-2.1.2 Cofferdams separating fuel oil tanks from lubricating oil tanks and the latter from those intended for the carriage of liquid foam for fire extinguishing or fresh water or boiler feed water may not be required when deemed impracticable or unreasonable by the Society in relation to the characteristics and dimensions of the spaces containing such tanks, provided that: - the thickness of common boundary plates of adjacent tanks is increased, with respect to the thickness obtained according to Ch 5, Sec 5, [4] by 2 mm in the case of tanks carrying fresh water or boiler feed water, and by 1 mm in all other cases - the sum of the throats of the weld fillets at the edges of these plates is not less than the thickness of the plates themselves - the structural test is carried out with a head increased by 1 m with respect to Ch 3, Sec 4, [5.1]. | S16: x | U16: =IF(OR(NOT(H16=""),NOT(M16="")),"","x")
A17: 311 | B17: =IFERROR(VLOOKUP(A17,Systems!A:B,2,FALSE),"Various") -> Bilge system | C17: Bilge wells in double bottoms | F17: Battery room | H17: B-2-2-3.1.3 Small wells constructed in the double bottom in connection with drainage arrangement are not to extend downward more than necessary. The vertical distance from the bottom of such a well to a plane coinciding with the keel line is not to be less than h/2 or 500 mm, whichever is greater, or compliance with requirement defined in Ch 3, Sec 3, [3.4.3] is to be shown for that part of the ship. Other wells (e.g. for lubricating oil under main engines) may be permitted by the Society if satisfied that the arrangements give protection equivalent to that afforded by a double bottom complying with this regulation. Proof of equivalent protection is to be shown by demonstrating that the ship is capable of withstanding bottom damages as specified in Ch 3, Sec 3, [3.4.3]. Alternatively, wells for lubricating oil below main engines may protrude into the double bottom below the boundary line defined by the distance h provided that the vertical distance between the well bottom and a plane coinciding with the keel line is not less than h/2 or 500 mm, whichever is the greater. For a cargo ship of less than 80 m in length, the arrangements are to provide a level of safety to the satisfaction of the Society. | P17: B-2-1-2.1.4 Where a corner to corner situation occurs, tanks are not be considered to be adjacent. Adjacent tanks not separated by cofferdams are to have adequate dimensions to ensure easy inspection. | S17: x | U17: =IF(OR(NOT(H17=""),NOT(M17="")),"","x")
A18: 100 | B18: =IFERROR(VLOOKUP(A18,Systems!A:B,2,FALSE),"Various") -> Tank arrangement | C18: Peak tanks | F18: Battery room | H18: B-2-2-4.1 The fore peak and other compartments located forward of the collision bulkhead cannot be used for the carriage of fuel oil or other flammable products. | P18: B-2-1-2.2.1 The fore peak and other compartments located forward of the collision bulkhead cannot be used for the carriage of fuel oil or other flammable products. | S18: x | U18: =IF(OR(NOT(H18=""),NOT(M18="")),"","x")
A19: 100 | B19: =IFERROR(VLOOKUP(A19,Systems!A:B,2,FALSE),"Various") -> Tank arrangement | C19: Fuel oil tanks | D19: 15-3-3.17.1 In a yacht in which fuel oil is used, the arrangements for the storage, distribution and utilisation of the fuel oil are to be such as to ensure the safety of the yacht and persons on board. For details, see Pt 15, Ch 3 Machinery Piping Systems. | F19: Battery room | H19: B-2-2-8.1.1 The arrangements for the storage, distribution and utilisation of the fuel oil are to be such as to ensure the safety of the ship and persons on board. | S19: x | U19: =IF(OR(NOT(H19=""),NOT(M19="")),"","x")
A20: 100 | B20: =IFERROR(VLOOKUP(A20,Systems!A:B,2,FALSE),"Various") -> Tank arrangement | C20: Fuel oil tanks | D20: 15-3-3.17.2 As far as practicable, fuel oil tanks are to be part of the yacht's structure and are to be located outside Category ‘A' machinery spaces. 15-3-3.17.3 Where fuel oil tanks, other than double bottom tanks, are necessarily located adjacent to or within Category ‘A' machinery spaces, at least one of their vertical sides is to be contiguous to the machinery space boundaries, and is preferably to have a common boundary with the double bottom tanks, and the area of the tank boundary common with the machinery spaces is to be kept to a minimum. Where the vertical boundary of a tank directly exposed to a machinery space meets the yacht's side plating at an acute angle, a small horizontal surface at the base of the tank, necessary to accommodate practical constructional considerations may be permitted. If the arrangement of the machinery is such that a tank with a large horizontal surface at the base is necessary then a cofferdam with suitable ventilation arrangements, to protect the base of the tank from the effect of a machinery space fire, will be specially considered. See also Pt 15, Ch 3 Machinery Piping Systems. Fuel oil tanks situated within the boundaries of Category ‘A' machinery spaces are not to contain fuel oil having a flashpoint of less than 60°C. The use of free-standing fuel oil tanks is prohibited. | F20: Battery room | H20: B-2-2-8.1.2 As far as practicable, fuel oil tanks are to be part of the ship's structure and are to be located outside machinery spaces of category A. Where fuel oil tanks, other than double bottom tanks, are necessarily located adjacent to or within machinery spaces of category A, at least one of their vertical sides is to be contiguous to the machinery space boundaries, they are preferably to have a common boundary with the double bottom tanks and the area of the tank boundary common with the machinery spaces is to be kept to a minimum. Where such tanks are situated within the boundaries of machinery spaces of category A, they may not contain fuel oil having a flashpoint of less than 60°C. | S20: x | U20: =IF(OR(NOT(H20=""),NOT(M20="")),"","x")
A21: 100 | B21: =IFERROR(VLOOKUP(A21,Systems!A:B,2,FALSE),"Various") -> Tank arrangement | C21: Fuel oil tanks | F21: Battery room | H21: B-2-2-8.1.3 Fuel oil tanks may not be located where spillage or leakage therefrom can constitute a hazard by falling on heated surfaces. Precautions are to be taken to prevent any oil that may escape under pressure from any pump, filter or heater from coming into contact with heated surfaces. Fuel oil tanks in boiler spaces may not be located immediately above the boilers or in areas subjected to high temperatures, unless special arrangements are provided in agreement with the Society. | S21: x | U21: =IF(OR(NOT(H21=""),NOT(M21="")),"","x")
A22: 132 | B22: =IFERROR(VLOOKUP(A22,Systems!A:B,2,FALSE),"Various") -> Manholes / manhole covers | C22: Double bottom | F22: Battery room | H22: B-2-3-2.1 Inner bottom manholes Inner bottom manholes are to be not less than 0,40 m x 0,40 m. Their number and location are to be so arranged as to provide convenient access to any part of the double bottom. Inner bottom manholes are to be closed by watertight plate covers. Doubling plates are to be fitted on the covers, where secured by bolts. Where no ceiling is fitted, covers are to be adequately protected from damage by the cargo. | P22: B-2-1-3.1.1 Inner bottom manholes Inner bottom manholes are to be not less than 0,40 m x 0,40 m. Their number and location are to be so arranged as to provide convenient access to any part of the double bottom. Inner bottom manholes are to be closed by watertight plate covers. Doubling plates are to be fitted on the covers, where secured by bolts. Where no ceiling is fitted, covers are to be adequately protected from damage by the cargo. | S22: x | U22: =IF(OR(NOT(H22=""),NOT(M22="")),"","x")
A23: 143 | B23: =IFERROR(VLOOKUP(A23,Systems!A:B,2,FALSE),"Various") -> Platforms / gratings | C23: Double bottom | F23: Battery room | H23: B-2-3-2.2 Floor and girder manholes Manholes are to be provided in floors and girders so as to provide convenient access to all parts of the double bottom. The size of manholes and lightening holes in floors and girders is, in general, to be less than 50 per cent of the local height of the double bottom. Where manholes of greater sizes are needed, edge reinforcement by means of flat bar rings or other suitable stiffeners may be required. Manholes may not be cut into the continuous centreline girder or floors and girders below pillars, except where allowed by the Society on a case by case basis. | P23: B-2-1-3.1.2 Floor and girder manholes Manholes are to be provided in floors and girders so as to provide convenient access to all parts of the double bottom. The size of manholes and lightening holes in floors and girders is, in general, to be less than 50 per cent of the local height of the double bottom. Where manholes of greater sizes are needed, edge reinforcement by means of flat bar rings or other suitable stiffeners may be required. Manholes may not be cut into the continuous centreline girder or floors and girders below pillars, except where allowed by the Society on a case by case basis. | S23: x | U23: =IF(OR(NOT(H23=""),NOT(M23="")),"","x")
A24: 132 | B24: =IFERROR(VLOOKUP(A24,Systems!A:B,2,FALSE),"Various") -> Manholes / manhole covers | C24: Access to tanks | F24: Battery room | H24: B-2-3-3.2.1 Tanks and subdivisions of tanks having lengths of 35 m and above are to be fitted with at least two access hatchways and ladders, as far apart as practicable longitudinally. Tanks less than 35 m in length are to be served by at least one access hatchway and ladder. | P24: B-2-1-3.2.1 Tanks and subdivisions of tanks having lengths of 35 m and above are to be fitted with at least two access hatchways and ladders, as far apart as practicable longitudinally. Tanks less than 35 m in length are to be served by at least one access hatchway and ladder. | S24: x | U24: =IF(OR(NOT(H24=""),NOT(M24="")),"","x")
A25: 132 | B25: =IFERROR(VLOOKUP(A25,Systems!A:B,2,FALSE),"Various") -> Manholes / manhole covers | C25: Access to tanks | F25: Battery room | H25: B-2-3-3.2.2 The dimensions of any access hatchway are to be sufficient to allow a person wearing a self-contained breathing apparatus to ascend or descend the ladder without obstruction and also to provide a clear opening to facilitate the hoisting of an injured person from the bottom of the tank. In no case is the clear opening to be less than 0,36 m2 and its length 0,50 m. | P25: B-2-1-3.2.2 The dimensions of any access hatchway are to be sufficient to allow a person wearing a self-contained breathing apparatus to ascend or descend the ladder without obstruction and also to provide a clear opening to facilitate the hoisting of an injured person from the bottom of the tank. In no case is the clear opening to be less than 0,36 m2 and its length 0,50 m. | S25: x | U25: =IF(OR(NOT(H25=""),NOT(M25="")),"","x")
A26: 132 | B26: =IFERROR(VLOOKUP(A26,Systems!A:B,2,FALSE),"Various") -> Manholes / manhole covers | C26: Access within tanks | F26: Battery room | H26: B-2-3-3.3.4 Manholes Where manholes are fitted, access is to be facilitated by means of steps and hand grips with platform landings on each side. | P26: B-2-1-3.3.2 Manholes Where manholes are fitted, access is to be facilitated by means of steps and hand grips with platform landings on each side. | S26: x | U26: =IF(OR(NOT(H26=""),NOT(M26="")),"","x")
A27: 311 312 313 346 | B27: =IFERROR(VLOOKUP(A27,Systems!A:B,2,FALSE),"Various") -> Various | C27: Progressive flooding - Definition | F27: Battery room | H27: B-3-3-3.3.1 Progressive flooding is the additional flooding of spaces which were not previously assumed to be damaged. Such additional flooding may occur through openings or pipes as indicated in [3.3.2] and [3.3.3]. | S27: x | T27: x | U27: =IF(OR(NOT(H27=""),NOT(M27="")),"","x")
A28: 311 312 313 346 | B28: =IFERROR(VLOOKUP(A28,Systems!A:B,2,FALSE),"Various") -> Various | C28: Progressive flooding - Openings categories | F28: Battery room | H28: B-3-3-3.3.2 Openings The openings may be listed in the following categories, depending on their means of closure: - Unprotected openings may lead to progressive flooding if they are situated within the range of the positive righting lever curve or if they are located below the waterline after damage (at any stage of flooding ). Unprotected openings are openings which are not fitted with at least weathertight means of closure, or ventilators that have to remain open to supply air to the engine room or emergency generator room for the effective operation of the ship. - Openings fitted with weathertight means of closure are not able to sustain a constant head of water, but they can be intermittently immersed within the positive range of stability. Weathertight openings may lead to progressive flooding if they are located below the waterline after damage (at any stage of flooding ). - Internal openings fitted with semi-watertight means of closure are able to sustain a constant head of water corresponding to the immersion relevant to the highest waterline after damage at the equilibrium of the intermediate stages of flooding. Semi-watertight openings may lead to progressive flooding if they are located below the final equilibrium waterline after damage. - Internal openings fitted with watertight means of closure are able to sustain a constant head of water corresponding to the distance between the lowest edge of this opening and the bulkhead/freeboard deck. Air pipe closing devices complying with Pt C, Ch 1, Sec 10, [9.1.6] may not be considered watertight, unless additional arrangements are fitted in order to demonstrate that such closing devices are effectively watertight. The pressure/vacuum valves (PV valves) currently installed on tankers do not theoretically provide complete watertightness. Manhole covers may be considered watertight provided the cover is fitted with bolts located such that the distance between their axes is less than five times the bolt's diameter. Access hatch covers leading to tanks may be considered watertight. Watertight openings do not lead to progressive flooding . | S28: x | U28: =IF(OR(NOT(H28=""),NOT(M28="")),"","x")
A29: 311 312 313 346 | B29: =IFERROR(VLOOKUP(A29,Systems!A:B,2,FALSE),"Various") -> Various | C29: Progressive flooding - Through pipes | F29: Battery room | H29: B-3-3-3.3.3 Progressive flooding through pipes may occur when: - the pipes and connected valves are located within the assumed damage, and no valves are fitted outside the damage - the pipes, even if located outside the damage, satisfy all of the following conditions: -- the pipe connects a damaged space to one or more spaces located outside the damage -- the highest vertical position of the pipe is below the waterline, and -- no valves are fitted. The possibility of progressive flooding through ballast piping passing through the assumed extent of damage, where positive action valves are not fitted to the ballast system at the open ends of the pipes in the tanks served, is to be considered. Where remote control systems are fitted to ballast valves and these controls pass through the assumed extent of damage, then the effect of damage to the system is to be considered to ensure that the valves would remain closed in that event. If pipes, ducts or tunnels are situated within assumed flooded compartments, arrangements are to be made to ensure that progressive flooding cannot thereby extend to compartments other than those assumed flooded. However, the Society may permit minor progressive flooding if it is demonstrated that the additional flooding of those compartments cannot lead to the capsizing or the sinking of the ship. Requirements relative to the prevention of progressive flooding are specified in Pt C, Ch 1, Sec 10, [5.5]. | J29: 1-3-3.3.1 If pipes, ducts trunks or tunnels are situated within the assumed extent of damage, arrangements are to be made to ensure that progressive flooding cannot thereby extend to compartments other than those assumed to be floodable for each case of damage. | L29: MSC/Circular.406/Rev.1 - Guidelines 3 | S29: x | U29: =IF(OR(NOT(H29=""),NOT(M29="")),"","x")
A30: 102 31x 331 341 | B30: =IFERROR(VLOOKUP(A30,Systems!A:B,2,FALSE),"Various") -> Various | C30: Hull piping - Material | F30: Battery room | H30: B-6-7-5.1.1 The scuppers and discharge pipes are to be constructed of steel. Other equivalent materials are considered by the Society on a case by case basis. | P30: B-6-7-5.1.1 The scuppers and discharge pipes are to be constructed of steel. Other equivalent materials are considered by the Society on a case by case basis. | S30: x | U30: =IF(OR(NOT(H30=""),NOT(M30="")),"","x")
A31: 311 | B31: =IFERROR(VLOOKUP(A31,Systems!A:B,2,FALSE),"Various") -> Bilge system | C31: Arrangement | F31: IGC Code | G31: 3.7.1.1. Where cargo is carried in a cargo containment system not requiring a secondary barrier, hold spaces should be provided with suitable drainage arrangements not connected with the machinery space. Means of detecting any leakage should be provided.
A32: 311 | B32: =IFERROR(VLOOKUP(A32,Systems!A:B,2,FALSE),"Various") -> Bilge system | C32: Arrangement | F32: IGC Code | G32: 3.7.1.2. Where there is a secondary barrier, suitable drainage arrangements for dealing with any leakage into the hold or insulation spaces through adjacent ship structure should be provided. The suction should not be led to pumps inside the machinery space. Means of detecting such leakage should be provided.
A33: 311 | B33: =IFERROR(VLOOKUP(A33,Systems!A:B,2,FALSE),"Various") -> Bilge system | C33: Arrangement | F33: IGC Code | G33: 3.7.2.1. The hold or interbarrier spaces of Type A independent tank ships should be provided with a drainage system suitable for handling liquid cargo in the event of cargo tank leakage or rupture. Such arrangements should provide for the return of any cargo leakage to the liquid cargo piping.
A34: 311 | B34: =IFERROR(VLOOKUP(A34,Systems!A:B,2,FALSE),"Various") -> Bilge system | C34: Arrangement | F34: IGC Code | G34: 3.7.2.2. Arrangements referred to in 3.7.2.1 should be provided with a removable spool piece.
A35: 311 | B35: =IFERROR(VLOOKUP(A35,Systems!A:B,2,FALSE),"Various") -> Bilge system | C35: Arrangement | F35: IGC Code | G35: 3.7.3. In case of internal insulation tanks, means of detecting leakage and drainage arrangements are not required for interbarrier spaces and spaces between the secondary barrier and the inner hull or independent tank structure which are completely filled by insulation material complying with 4.9.7.2
A36: 312 | B36: =IFERROR(VLOOKUP(A36,Systems!A:B,2,FALSE),"Various") -> Ballast system | C36: Arrangement | F36: IGC Code | G36: 3.7.4. Ballast spaces, including wet duct keels used as ballast piping, fuel-oil tanks and gas-safe spaces may be connected to pumps in the machinery spaces. Dry duct keels with ballast piping passing through, may be connected to pumps in the machinery spaces, provided the connections are led directly to the pumps and the discharge from the pumps lead directly overboard with no valves or manifolds in either line which could connect the line from the duct keel to lines serving gas-safe spaces. Pump vents should not be open to machinery spaces.
A37: 321 | B37: =IFERROR(VLOOKUP(A37,Systems!A:B,2,FALSE),"Various") -> Fuel transfer system | C37: ESD valve requirements | F37: IGC Code | G37: 18.10.2.1.2 ESD valves shall be remotely operated, be of the fail-closed type (closed on loss of actuating power), be capable of local manual closure and have positive indication of the actual valve position. As an alternative to the local manual closing of the ESD valve, a manually operated shut-off valve in series with the ESD valve shall be permitted. The manual valve shall be located adjacent to the ESD valve. Provisions shall be made to handle trapped liquid should the ESD valve close while the manual valve is also closed.
A38: 321 | B38: =IFERROR(VLOOKUP(A38,Systems!A:B,2,FALSE),"Various") -> Fuel transfer system | C38: ESD valve requirements | F38: IGC Code | G38: 18.10.2.1.3 ESD valves in liquid piping systems shall close fully and smoothly within 30 s of actuation. Information about the closure time of the valves and their operatingcharacteristics shall be available on board, and the closing time shall be verifiable and repeatable.
A39: 321 | B39: =IFERROR(VLOOKUP(A39,Systems!A:B,2,FALSE),"Various") -> Fuel transfer system | C39: Ship-shore and ship-ship manifold connections | G39: 18.10.2.2 One ESD valve shall be provided at each manifold connection. Cargo manifold connections not being used for transfer operations shall be blanked with blank flanges rated for the design pressure of the pipeline system.
A40: 321 | B40: =IFERROR(VLOOKUP(A40,Systems!A:B,2,FALSE),"Various") -> Fuel transfer system | C40: Number of ESD valves | G40: 5.5.1.2 In addition, remotely operated valves shall also be fitted, as appropriate, as part of the emergency shutdown (ESD) system the purpose of which is to stop cargo flowor leakage in the event of an emergency when cargo liquid or vapour transfer is in progress. The ESD system is intended to return the cargo system to a safe static condition so that any remedial action can be taken. Due regard shall be given in the design of the ESD system to avoid the generation of surge pressures within the cargo transfer pipework. The equipment to be shut down on ESD activation includes manifold valves during loading or discharge, any pump or compressor, etc., transferring cargo internally or externally (e.g. to shore or another ship/barge) and cargo tank valves, if the MARVS exceeds 0.07 MPa.
...

Sheet Tables
A70: Wallthicknesses
A72: Steel pipes | I72: CO2 systems | R72: Copper and copper alloy pipes | W72: Stainless steel pipes | AJ72: Aluminium and aluminium alloy pipes

Sheet Public root
B3: Division | C3: Mechanical
B5: Bureau Veritas eRules | C5: Rules for the Classification of Inland Navigation Vessels - November 2014 edition (entry into force 1 February 2015)
B7: Ministry of Transportation of Ontario | C7: Technical Specification for the Design, Construction and Delivery of a 40 Vehicle Roll-on / Roll-off Passenger (Ro-Pax) Ferry

Sheet Systems
A1: SYSTEM | B1: DESCRIPTION
A2: 000 | B2: Project data
A3: 100 | B3: Tank arrangement
A4: 102 | B4: Hull connections
A5: 130 | B5: Hatches / doors / windows
A6: 131 | B6: Hatches
A7: 132 | B7: Manholes / manhole covers
A8: 133
A9: 134
A10: 135
A11: 136
A12: 137
A13: 139
A14: 140
A15: 141 | B15: Stairs / ladders / climbing steps
A16: 142 | B16: Railings / handrails / grips
A17: 143 | B17: Platforms / gratings
A18: 144
A19: 163 | B19: Cathodic protection
A20: 200 | B20: Main machinery
A21: 201
A22: 202
A23: 203
A24: 204
A25: 210
A26: 211 | B26: Propulsion engine system
A27: 212 | B27: Reduction gear system
A28: 213 | B28: Thrust systems / shafts
A29: 214
A30: 220
A31: 221
A32: 222 | B32: Steering gear system
A33: 223
A34: 224
A35: 250
A36: 251
A37: 252
A38: 253
A39: 254
A40: 255
...

Sheet Data
B2: Yes/no
B3: Yes
B4: No
B6: Publications
B7: NR467 Steelships - July 2018 edition (entry into force 1 July 2018)
B8: NR216 Materials and welding - Januari
B9: Offshore units
B10: Yachts
B11: Inland
B12: Floating
B13: Naval
B14: NR600
... B50: VCS
